2025-08-09 14:46:04,798 - __main__ - INFO - Iniciando el ciclo de vida de la aplicación. Mostrando pantalla de login.
2025-08-09 14:46:09,581 - sigvcf.auth.viewmodels - INFO - ViewModel: Intentando login para el usuario 'Jesus'.
2025-08-09 14:46:09,808 - sigvcf.auth.viewmodels - INFO - ViewModel: Login exitoso para 'Jesus'.
2025-08-09 14:46:09,808 - sigvcf.auth.viewmodels - ERROR - ViewModel: Error en el proceso de login: 'dict' object has no attribute 'id'
Traceback (most recent call last):
  File "/home/jesus-langarica/Documentos/sii_almv /sigvcf/auth/viewmodels.py", line 39, in intentar_login
    'id': usuario_autenticado.id,
          ^^^^^^^^^^^^^^^^^^^^^^
AttributeError: 'dict' object has no attribute 'id'
2025-08-09 14:46:12,041 - sigvcf.auth.viewmodels - INFO - ViewModel: Intentando login para el usuario 'Jesus'.
2025-08-09 14:46:12,245 - sigvcf.auth.viewmodels - INFO - ViewModel: Login exitoso para 'Jesus'.
2025-08-09 14:46:12,245 - sigvcf.auth.viewmodels - ERROR - ViewModel: Error en el proceso de login: 'dict' object has no attribute 'id'
Traceback (most recent call last):
  File "/home/jesus-langarica/Documentos/sii_almv /sigvcf/auth/viewmodels.py", line 39, in intentar_login
    'id': usuario_autenticado.id,
          ^^^^^^^^^^^^^^^^^^^^^^
AttributeError: 'dict' object has no attribute 'id'
2025-08-09 14:46:14,009 - __main__ - INFO - El usuario cerró la ventana de login o no se autenticó correctamente. La aplicación terminará.
